Workbook

Sheet LEIA-ME
A1: PoliVSR – Base de Dados do Modelo (v1, 09/10/2026)
A2: Planilha-mestre com as séries temporais e os parâmetros do modelo estocástico da calculadora "O Custo do Fixo". Todo número tem fonte: primária (ONS, ANEEL, BCB) na aba Fontes_Primarias, ou secundária (CIGRÉ, IEEE, IEC, fabricantes) na aba Fontes_Secundarias.
A4: Como usar
A5: 1. Parametros_Modelo: a tabela que alimenta a calculadora. Cada linha diz o valor, a unidade, para que serve no modelo, a fonte e a aba de origem.
A6: 2. Abas de dados: séries e estatísticas processadas. As linhas 1–3 de cada aba dizem de onde vêm os dados e o script que os gerou.
A7: 3. Reprodutibilidade: os arquivos brutos estão em raw/ e os scripts Python em scripts/ (00 a 05). Rodar na ordem regenera tudo. O manifesto traz o SHA-256 de cada arquivo bruto.
A9: Definições
A10: Carga líquida = demanda − (geração eólica + fotovoltaica centralizada + MMGD), por meia-hora, a partir do balanço DESSEM detalhado do ONS (valores programados).
A11: Amplitude diária = máximo − mínimo da carga líquida no dia. Rampa de 3 h = maior aumento da carga líquida em 6 meias-horas consecutivas.
A12: Disponibilidade FTRT = indicador DISP mensal do ONS para as Funções Transmissão de reator, agregado por nível de tensão.
A14: Limitações conhecidas
A15: • O cadastro do ONS não distingue reatores manobráveis de fixos; o número de manobráveis (≈ 530) vem do CIGRÉ A3-10747.
... A56: Fontes_Secundarias

Sheet Parametros_Modelo
A1: PoliVSR – Parâmetros do modelo com fonte
A2: Legenda: verde = valor vindo de outra aba (dado processado) · preto = fórmula · azul = valor de literatura digitado (ver Fontes_Secundarias) · amarelo = premissa-chave a confirmar.
A4: id | B4: grupo | C4: parametro | D4: valor | E4: unidade | F4: uso_no_modelo | G4: fonte | H4: aba_origem | I4: observacao
A5: P01 | B5: Reatores | C5: Reatores shunt ativos ≥ 230 kV | D5: =Resumo_Inventario!$C$7 -> 1084 | E5: un | F5: Universo do dashboard (substitui o placeholder "13") | G5: ONS – cadastro de equipamentos de controle de reativos | H5: Resumo_Inventario | I5: Bate com ≈ 1.100 do CIGRÉ A3-10747 (S05). O cadastro não informa quais são manobráveis.
A6: P02 | B6: Reatores | C6: Reatores manobráveis ≥ 230 kV (literatura) | D6: 530 | E6: un | F6: Universo de reatores sujeitos a manobra diária | G6: CIGRÉ A3-10747 (2026) | H6: Fontes_Secundarias | I6: Único número público de manobráveis; usar como cenário central.
A7: P03 | B7: Reatores | C7: Potência total dos reatores ativos ≥ 230 kV | D7: =Resumo_Inventario!$C$8 -> 126003 | E7: Mvar | F7: Escala do sistema | G7: ONS – cadastro | H7: Resumo_Inventario
A8: P04 | B8: Reatores | C8: Potência mediana por reator ≥ 230 kV | D8: =Resumo_Inventario!$C$12 -> 136 | E8: Mvar | F8: Tamanho típico do reator nos cenários | G8: ONS – cadastro | H8: Resumo_Inventario
A9: P05 | B9: Reatores | C9: Reatores ≥ 230 kV anteriores a 1991 | D9: =Reatores_Idade!$B$9 -> 185 | E9: un | F9: Candidatos a substituição por fim de vida útil | G9: ONS – cadastro | H9: Reatores_Idade | I9: Idade real ≥ 35,8 anos (data-padrão do cadastro).
A10: P06 | B10: Reatores | C10: Crescimento do estoque de reatores ≥ 230 kV, 2015→2026 | D10: =Reatores_SerieAnual!$E$36/Reatores_SerieAnual!$E$25-1 -> 0.97090909 | E10: % | F10: Tendência de demanda por compensação reativa | G10: ONS – cadastro | H10: Reatores_SerieAnual | I10: Estoque reconstruído a partir do cadastro atual.
A11: P07 | B11: Linhas | C11: Carregamento capacitivo mediano – 230 kV | D11: =Linhas_Mvar_km!$F$5 -> 0.182 | E11: Mvar/km | F11: Física do slider "Extensão do trecho" | G11: ONS – cadastro de linhas | H11: Linhas_Mvar_km | I11: p10–p90 na aba de origem.
A12: P08 | B12: Linhas | C12: Carregamento capacitivo mediano – 500 kV | D12: =Linhas_Mvar_km!$F$8 -> 1.451 | E12: Mvar/km | F12: Física do slider "Extensão do trecho" | G12: ONS – cadastro de linhas | H12: Linhas_Mvar_km | I12: p10 1,17; p90 2,13 (linhas compactas/LPNE puxam a cauda).
A13: P09 | B13: Linhas | C13: Grau de compensação shunt sistêmico 440–525 kV | D13: =Resumo_Inventario!$C$17 -> 0.832 | E13: pu | F13: Mvar de reator por Mvar de carregamento da linha | G13: ONS – cadastros de reatores e linhas | H13: Resumo_Inventario | I13: Razão agregada do SIN, não projeto de uma linha específica.
A14: P10 | B14: Disponibilidade | C14: Disponibilidade média mensal FTRT 500 kV (2011–2026) | D14: =Disp_FTRT_Estat!$E$8 -> 99.1008 | E14: % (escala 0–100) | F14: Base para indisponibilidade/PVI do reator fixo | G14: ONS – indicador DISP | H14: Disp_FTRT_Estat
A15: P11 | B15: Disponibilidade | C15: Indisponibilidade média FTRT 500 kV | D15: =Disp_FTRT_Estat!$H$8 -> 6.566 | E15: h/mês | F15: Horas fora de serviço por mês (média do nível de tensão) | G15: ONS – indicador DISP | H15: Disp_FTRT_Estat | I15: Inclui desligamentos programados e forçados.
A16: P12 | B16: Disponibilidade | C16: Indisponibilidade p95 FTRT 500 kV | D16: =Disp_FTRT_Estat!$I$8 -> 16.489 | E16: h/mês | F16: Cauda de risco | G16: ONS – indicador DISP | H16: Disp_FTRT_Estat
A17: P13 | B17: Curva de pato | C17: Amplitude diária média da carga líquida – SIN | D17: =CurvaPato_Estat!$E$9 -> 38100.2 | E17: MW | F17: Volatilidade-base do cenário nacional | G17: ONS – DESSEM detalhado | H17: CurvaPato_Estat | I17: mai/2025–out/2026; carga líquida = demanda − eólica − FV − MMGD.
A18: P14 | B18: Curva de pato | C18: Amplitude diária p95 – SIN | D18: =CurvaPato_Estat!$I$9 -> 45251.49 | E18: MW | F18: Cenário pessimista | G18: ONS – DESSEM detalhado | H18: CurvaPato_Estat
A19: P15 | B19: Curva de pato | C19: Rampa máxima de 3 h, média diária – SIN | D19: =CurvaPato_Estat!$J$9 -> 26545.28 | E19: MW | F19: Velocidade de variação que o controle de tensão acompanha | G19: ONS – DESSEM detalhado | H19: CurvaPato_Estat
A20: P16 | B20: Curva de pato | C20: Rampa máxima de 3 h no período – SIN | D20: =CurvaPato_Estat!$L$9 -> 43044.64 | E20: MW | F20: Evento extremo | G20: ONS – DESSEM detalhado | H20: CurvaPato_Estat
A21: P17 | B21: Curva de pato | C21: % de dias com mínimo da carga líquida entre 10h e 15h – SIN | D21: =CurvaPato_Estat!$P$9 -> 92.69 | E21: % (escala 0–100) | F21: Frequência do "vale do meio-dia" | G21: ONS – DESSEM detalhado | H21: CurvaPato_Estat
A22: P18 | B22: Curva de pato | C22: Amplitude diária média – Nordeste | D22: =CurvaPato_Estat!$E$6 -> 10626.84 | E22: MW | F22: Cenários Campo/Indústria | G22: ONS – DESSEM detalhado | H22: CurvaPato_Estat | I22: Desvio-padrão e percentis na aba de origem.
A23: P19 | B23: Curva de pato | C23: Coeficiente de variação da amplitude – Nordeste | D23: =CurvaPato_Estat!$Q$6 -> 0.25 | E23: adim. | F23: Dispersão para a simulação de Monte Carlo | G23: ONS – DESSEM detalhado | H23: CurvaPato_Estat
A24: P20 | B24: Curva de pato | C24: Amplitude diária média – Sudeste/Centro-Oeste | D24: =CurvaPato_Estat!$E$8 -> 24298.05 | E24: MW | F24: Cenário Centro Urbano | G24: ONS – DESSEM detalhado | H24: CurvaPato_Estat
A25: P21 | B25: Carga histórica | C25: Variação da amplitude diária média do SIN, 2019→2025 | D25: =Carga_Anual!$D$63/Carga_Anual!$D$57-1 -> 0.13274191 | E25: % | F25: Tendência da volatilidade | G25: ONS – curva de carga horária | H25: Carga_Anual | I25: Anos completos; 2026 é parcial.
A26: P22 | B26: Carga histórica | C26: % de dias com mínimo entre 10h e 15h – NE, 2015 | D26: =Carga_Anual!$H$17 -> 0 | E26: % (escala 0–100) | F26: Linha de base antes da MMGD | G26: ONS – curva de carga horária | H26: Carga_Anual
A27: P23 | B27: Carga histórica | C27: % de dias com mínimo entre 10h e 15h – NE, 2026 (parcial) | D27: =Carga_Anual!$H$28 -> 35 | E27: % (escala 0–100) | F27: Evidência da curva de pato no NE | G27: ONS – curva de carga horária | H27: Carga_Anual | I27: Até 07/10/2026.
A28: P24 | B28: MMGD | C28: Estoque de MMGD – Brasil (último mês da base) | D28: =MMGD_Mensal_Regiao!$G$176 -> 53.874 | E28: GW | F28: Motor da volatilidade | G28: ANEEL – empreendimentos de GD | H28: MMGD_Mensal_Regiao | I28: Últimos meses podem ter atraso de registro.
A29: P25 | B29: MMGD | C29: Estoque de MMGD – Nordeste | D29: =MMGD_Mensal_Regiao!$C$176 -> 11.038 | E29: GW | F29: Calibrar volatilidade regional | G29: ANEEL – empreendimentos de GD | H29: MMGD_Mensal_Regiao
A30: P26 | B30: MMGD | C30: MMGD adicionada em 2025 | D30: =MMGD_Anual!$B$18 -> 9.599 | E30: GW | F30: Ritmo de crescimento | G30: ANEEL – empreendimentos de GD | H30: MMGD_Anual
A31: P27 | B31: Custos | C31: Disjuntor 500 kV – preço de referência (base mai/2017) | D31: =BPR_Disjuntor!$C$12 -> 1870921.6 | E31: R$ | F31: Custo de troca do disjuntor | G31: ANEEL – BPR | H31: BPR_Disjuntor | I31: Item "Disjuntor", classe UAR.
A32: P28 | B32: Custos | C32: Disjuntor 500 kV – corrigido pelo IPCA | D32: =BPR_Disjuntor!$E$12 -> 2972656.8 | E32: R$ | F32: Custo de troca do disjuntor (valores atuais) | G32: ANEEL – BPR + BCB IPCA | H32: BPR_Disjuntor | I32: Correção por fórmula; muda se o mês final em BPR_Disjuntor!E3 for alterado.
A33: P29 | B33: Custos | C33: Disjuntor 230 kV – corrigido pelo IPCA | D33: =BPR_Disjuntor!$E$9 -> 464004.56 | E33: R$ | F33: Custo de troca do disjuntor (cenários 230 kV) | G33: ANEEL – BPR + BCB IPCA | H33: BPR_Disjuntor
A34: P30 | B34: Custos | C34: Participação do disjuntor no módulo CRB 500 kV (arranjo DJM) | D34: =BPR_CRB_Disjuntor!$E$20 -> 35.5 | E34: % (escala 0–100) | F34: Peso do disjuntor no custo de conexão do reator | G34: ANEEL – BPR | H34: BPR_CRB_Disjuntor | I34: Arranjos AN e BDDD na aba de origem (32% a 47%).
A35: P31 | B35: Financeiro | C35: WACC regulatório transmissão – real pós-impostos (2026) | D35: 0.08 | E35: % | F35: Taxa de desconto do VPL/payback | G35: ANEEL, via imprensa (S09, S10) | H35: Fontes_Secundarias | I35: Confirmar no ato publicado no DOU de 04/03/2026.
A36: P32 | B36: Financeiro | C36: WACC regulatório transmissão – real pré-impostos (2026) | D36: 0.1211 | E36: % | F36: Sensibilidade | G36: ANEEL, via imprensa (S09, S10) | H36: Fontes_Secundarias
A37: P33 | B37: Financeiro | C37: IPCA acumulado em 12 meses (último mês) | D37: =Macro_Mensal!$H$205 -> 4.5761 | E37: % (escala 0–100) | F37: Correção de custos | G37: BCB – SGS 433 | H37: Macro_Mensal
A38: P34 | B38: Financeiro | C38: Juro real ex-post 12 meses (Selic ÷ IPCA) | D38: =Macro_Mensal!$J$205 -> 9.4598 | E38: % (escala 0–100) | F38: Custo de oportunidade alternativo | G38: BCB – SGS 4390 e 433 | H38: Macro_Mensal
A39: P35 | B39: Financeiro | C39: Câmbio US$/R$ (média do último mês) | D39: =Macro_Mensal!$E$205 -> 5.1447 | E39: R$/US$ | F39: Converter preços de equipamento em dólar | G39: BCB – SGS 3698 | H39: Macro_Mensal
A40: P36 | B40: Financeiro | C40: Câmbio €/R$ (média do último mês) | D40: =Macro_Mensal!$G$205 -> 5.9186 | E40: R$/€ | F40: Converter preços de equipamento em euro | G40: BCB – SGS 21619 | H40: Macro_Mensal
A41: P37 | B41: Confiabilidade (literatura) | C41: Taxa de falha grave de disjuntores SF6 (média mundial) | D41: 0.3 | E41: falhas/100 disjuntores-ano | F41: Taxa-base do modelo de falhas | G41: CIGRÉ TB 510 (S01) | H41: Fontes_Secundarias | I41: Manobra de reator tem a maior taxa entre as aplicações.
...

Sheet Resumo_Inventario
A1: Resumo do inventário de reatores, linhas e disponibilidade
A2: Fonte: ONS – Portal de Dados Abertos (dados.ons.org.br), acesso em 09/10/2026, licença cc-by. Conjuntos equipamento-controle-reativo, linha-transmissao, ind_disponibilidade_ft_reativo. Script: scripts/01_inventario_reatores_linhas.py
A4: secao | B4: indicador | C4: valor | D4: unidade | E4: nota
A5: Reatores | B5: Reatores no cadastro (todos os registros) | C5: 1220 | D5: un
A6: Reatores | B6: Reatores ativos (sem data de desativação) | C6: 1149 | D6: un
A7: Reatores | B7: Reatores ativos ≥ 230 kV | C7: 1084 | D7: un | E7: comparar com ~1.100 bancos do CIGRÉ A3-10747 (2026)
A8: Reatores | B8: Potência total ativa ≥ 230 kV | C8: 126003 | D8: Mvar
A9: Reatores | B9: Idade mediana (ativos ≥ 230 kV) | C9: 10.2 | D9: anos
A10: Reatores | B10: Reatores ativos ≥ 230 kV com 30+ anos | C10: 186 | D10: un | E10: inclui os com data-padrão 1990-12-31 (idade real ≥ 35,8 anos)
A11: Reatores | B11: Reatores ativos ≥ 230 kV com data-padrão 1990-12-31 (pré-1991) | C11: 185 | D11: un | E11: idade é limite inferior
A12: Reatores | B12: Potência mediana por reator (≥ 230 kV) | C12: 136 | D12: Mvar
A13: Linhas | B13: Linhas CA ativas analisadas (com susceptância) | C13: 1671 | D13: un | E13: LINHA_TRANSMISSAO.csv; val_shunt = Mvar de carregamento (convenção ANAREDE)
A14: Linhas | B14: Extensão total das linhas analisadas | C14: 173541 | D14: km
A15: Linhas | B15: Grau de compensação shunt sistêmico 230 kV (reatores ÷ carregamento) | C15: 0.366 | D15: pu | E15: reatores 5496 Mvar / carregamento 15034 Mvar
A16: Linhas | B16: Grau de compensação shunt sistêmico 345 kV (reatores ÷ carregamento) | C16: 0.242 | D16: pu | E16: reatores 1774 Mvar / carregamento 7339 Mvar
A17: Linhas | B17: Grau de compensação shunt sistêmico 440-525 kV (reatores ÷ carregamento) | C17: 0.832 | D17: pu | E17: reatores 112299 Mvar / carregamento 135033 Mvar
A18: Linhas | B18: Grau de compensação shunt sistêmico 765 kV (reatores ÷ carregamento) | C18: 0.832 | D18: pu | E18: reatores 6434 Mvar / carregamento 7736 Mvar
A19: Disponibilidade | B19: FTRT - 230: disponibilidade média mensal | C19: 98.448 | D19: % | E19: 189 meses, 2011-01 a 2026-09; dp 0.8331
A20: Disponibilidade | B20: FTRT - 345: disponibilidade média mensal | C20: 99.1675 | D20: % | E20: 189 meses, 2011-01 a 2026-09; dp 1.5143
A21: Disponibilidade | B21: FTRT - 440: disponibilidade média mensal | C21: 98.1595 | D21: % | E21: 189 meses, 2011-01 a 2026-09; dp 2.6744
A22: Disponibilidade | B22: FTRT - 500: disponibilidade média mensal | C22: 99.1008 | D22: % | E22: 189 meses, 2011-01 a 2026-09; dp 0.6671
A23: Disponibilidade | B23: FTRT - 765: disponibilidade média mensal | C23: 95.9412 | D23: % | E23: 189 meses, 2011-01 a 2026-09; dp 11.7674

Sheet Reatores_Subsistema
A1: Reatores shunt ativos ≥ 230 kV por subsistema e faixa de tensão
A2: Fonte: ONS – Portal de Dados Abertos (dados.ons.org.br), acesso em 09/10/2026, licença cc-by. EQP_CONTROLE_REATIVO.csv (cadastro de equipamentos de controle de reativos da Rede de Operação).
A4: id_subsistema | B4: qtd_138-230 kV | C4: qtd_345 kV | D4: qtd_440-525 kV | E4: qtd_765 kV | F4: Mvar_138-230 kV | G4: Mvar_345 kV | H4: Mvar_440-525 kV | I4: Mvar_765 kV
A5: N | B5: 48 | C5: 0 | D5: 132 | E5: 0 | F5: 780 | G5: 0 | H5: 20873.68 | I5: 0
A6: NE | B6: 57 | C6: 0 | D6: 235 | E6: 0 | F6: 832.07 | G6: 0 | H6: 36645.9 | I6: 0
A7: S | B7: 26 | C7: 0 | D7: 93 | E7: 0 | F7: 742 | G7: 0 | H7: 11852.8 | I7: 0
A8: SE | B8: 138 | C8: 23 | D8: 312 | E8: 20 | F8: 3141.91 | G8: 1774.2 | H8: 42926.24 | I8: 6434
A9: SIN (total) | B9: 269 | C9: 23 | D9: 772 | E9: 20 | F9: 5495.98 | G9: 1774.2 | H9: 112298.62 | I9: 6434

Sheet Reatores_UF
A1: Reatores shunt ativos ≥ 230 kV por UF
A2: Fonte: ONS – Portal de Dados Abertos (dados.ons.org.br), acesso em 09/10/2026, licença cc-by. EQP_CONTROLE_REATIVO.csv.
A4: id_estado | B4: qtd | C4: Mvar | D4: idade_mediana
A5: MG | B5: 131 | C5: 17659.8 | D5: 5.6
A6: BA | B6: 117 | C6: 16120.29 | D6: 6.4
A7: MT | B7: 95 | C7: 8099.84 | D7: 14.9
A8: SP | B8: 91 | C8: 14037.7 | D8: 19.2
A9: PA | B9: 68 | C9: 8610.96 | D9: 13.3
A10: PI | B10: 64 | C10: 9704.98 | D10: 8.6
A11: RS | B11: 61 | C11: 5247.8 | D11: 5.1
A12: MA | B12: 50 | C12: 5642.86 | D12: 23
A13: CE | B13: 49 | C13: 4758.8 | D13: 16.4
A14: PR | B14: 41 | C14: 7277 | D14: 4.6
A15: GO | B15: 41 | C15: 4682.38 | D15: 14.6
A16: TO | B16: 36 | C16: 4562.66 | D16: 18.4
... A31: SE | B31: 4 | C31: 490 | D31: 3.9

Sheet Reatores_Idade
A1: Distribuição de idade dos reatores ativos ≥ 230 kV (em 09/10/2026)
A2: Fonte: ONS – Portal de Dados Abertos (dados.ons.org.br), acesso em 09/10/2026, licença cc-by. EQP_CONTROLE_REATIVO.csv.
A3: Atenção: 185 reatores têm data de entrada 1990-12-31, uma data-padrão do cadastro para equipamentos anteriores a 1991; a idade real deles é ≥ 35,8 anos.
A4: faixa_idade_anos | B4: qtd_reatores
A5: 0-9 | B5: 526
A6: 10-19 | B6: 272
A7: 20-29 | B7: 100
A8: 30+ (data real) | B8: 1
A9: pré-1991 (data-padrão 1990-12-31) | B9: 185

Sheet Reatores_SerieAnual
A1: Série anual de entradas e desativações de reatores ≥ 230 kV
A2: Fonte: ONS – Portal de Dados Abertos (dados.ons.org.br), acesso em 09/10/2026, licença cc-by. EQP_CONTROLE_REATIVO.csv (datas de entrada e desativação).
A3: Estoque reconstruído só a partir do cadastro atual; equipamentos pré-1991 aparecem todos em 1990 (data-padrão).
A4: ano | B4: entradas | C4: Mvar_entrada | D4: desativacoes | E4: estoque_fim_ano
A5: 1988 | B5: 1 | C5: 20 | D5: 0 | E5: 1
A6: 1990 | B6: 205 | C6: 21882.34 | D6: 4 | E6: 202
A7: 1997 | B7: 0 | C7: 0 | D7: 1 | E7: 201
A8: 1998 | B8: 1 | C8: 100 | D8: 0 | E8: 202
A9: 1999 | B9: 5 | C9: 731.8 | D9: 0 | E9: 207
A10: 2000 | B10: 2 | C10: 40 | D10: 1 | E10: 208
A11: 2001 | B11: 6 | C11: 760 | D11: 1 | E11: 213
A12: 2002 | B12: 13 | C12: 1284.17 | D12: 2 | E12: 224
A13: 2003 | B13: 37 | C13: 4628.72 | D13: 0 | E13: 261
A14: 2004 | B14: 15 | C14: 1282.72 | D14: 1 | E14: 275
A15: 2005 | B15: 20 | C15: 2216.99 | D15: 0 | E15: 295
A16: 2006 | B16: 32 | C16: 3657.27 | D16: 0 | E16: 327
... A36: 2026 | B36: 60 | C36: 7757.81 | D36: 3 | E36: 1084

Sheet Reatores_Lista
A1: Lista de reatores ativos (todas as tensões) – 1 linha por equipamento
A2: Fonte: ONS – Portal de Dados Abertos (dados.ons.org.br), acesso em 09/10/2026, licença cc-by. EQP_CONTROLE_REATIVO.csv; colunas kv, faixa_kv, idade_anos e data_padrao_pre1991 derivadas.
A4: cod_equipamento | B4: nom_equipamento | C4: id_subsistema | D4: id_estado | E4: nom_subestacao | F4: nom_agente_proprietario | G4: nom_tipoderede | H4: kv | I4: faixa_kv | J4: mvar | K4: dat_entradaoperacao | L4: idade_anos | M4: data_padrao_pre1991
A5: ALART-2RT1 | B5: RT 230 kV 15 Mvar ARAPIRACA III E1 AL | C5: NE | D5: AL | E5: ARAPIRACA III | F5: AXIA NORDESTE | G5: BASICA | H5: 230 | I5: 138-230 kV | J5: 15 | K5: 2013-06-14 | L5: 13.3 | M5: não
A6: ALMSI-5RT1 | B6: RT 500 kV 150 Mvar MESSIAS E1 AL | C6: NE | D6: AL | E6: MESSIAS | F6: AXIA NORDESTE | G6: BASICA | H6: 500 | I6: 440-525 kV | J6: 150 | K6: 1990-12-31 | L6: 35.8 | M6: sim
A7: ALPEN-2RT1 | B7: RT 230 kV 10 Mvar PENEDO E1 AL | C7: NE | D7: AL | E7: PENEDO | F7: AXIA NORDESTE | G7: BASICA | H7: 230 | I7: 138-230 kV | J7: 10 | K7: 2014-03-28 | L7: 12.5 | M7: não
A8: ALPEN-2RT2 | B8: RT 230 kV 10 Mvar PENEDO E2 AL | C8: NE | D8: AL | E8: PENEDO | F8: ETENE | G8: BASICA | H8: 230 | I8: 138-230 kV | J8: 10 | K8: 2021-01-08 | L8: 5.7 | M8: não
A9: SEXNG-5RT1 | B9: RT 500 kV 136 Mvar USINA XINGO E1 AL | C9: NE | D9: AL | E9: USINA XINGO | F9: PEDRAS | G9: BASICA | H9: 500 | I9: 440-525 kV | J9: 136 | K9: 2026-06-20 | L9: 0.3 | M9: não
A10: SEXNG-5RT2 | B10: RT 500 kV 136 Mvar USINA XINGO E2 AL | C10: NE | D10: AL | E10: USINA XINGO | F10: PEDRAS | G10: BASICA | H10: 500 | I10: 440-525 kV | J10: 136 | K10: 2026-06-20 | L10: 0.3 | M10: não
A11: BABJS-2RT3 | B11: RT 230 kV 10 Mvar B.JESUS LAPA E3 BA | C11: NE | D11: BA | E11: B.JESUS LAPA | F11: AXIA NORDESTE | G11: BASICA | H11: 230 | I11: 138-230 kV | J11: 10 | K11: 1990-12-31 | L11: 35.8 | M11: sim
A12: BABJS-2RT1 | B12: RT 230 kV 15 Mvar B.JESUS LAPA E1 BA | C12: NE | D12: BA | E12: B.JESUS LAPA | F12: AXIA NORDESTE | G12: BASICA | H12: 230 | I12: 138-230 kV | J12: 15 | K12: 1990-12-31 | L12: 35.8 | M12: sim
A13: BABJS-2RT2 | B13: RT 230 kV 15 Mvar B.JESUS LAPA E2 BA | C13: NE | D13: BA | E13: B.JESUS LAPA | F13: AXIA NORDESTE | G13: BASICA | H13: 230 | I13: 138-230 kV | J13: 15 | K13: 1990-12-31 | L13: 35.8 | M13: sim
A14: BABJS-0RT4 | B14: RT 13P8 kV 5P0 Mvar B.JESUS LAPA E1 BA | C14: NE | D14: BA | E14: B.JESUS LAPA | F14: AXIA NORDESTE | G14: BASICA | H14: 13.8 | I14: <100 kV | J14: 5 | K14: 1990-12-31 | L14: 35.8 | M14: sim
A15: BABJS-0RT5 | B15: RT 13P8 kV 5P0 Mvar B.JESUS LAPA E2 BA | C15: NE | D15: BA | E15: B.JESUS LAPA | F15: AXIA NORDESTE | G15: BASICA | H15: 13.8 | I15: <100 kV | J15: 5 | K15: 1990-12-31 | L15: 35.8 | M15: sim
A16: BABRA-2RT1 | B16: RT 230 kV 10 Mvar BARREIRAS E1 BA | C16: NE | D16: BA | E16: BARREIRAS | F16: AXIA NORDESTE | G16: BASICA | H16: 230 | I16: 138-230 kV | J16: 10 | K16: 1990-12-31 | L16: 35.8 | M16: sim
... A1153: SCSID25RT3 | B1153: RT 525 kV 150 Mvar SIDEROPOLIS 2 9RE02 SC | C1153: S | D1153: SC | E1153: SIDEROPOLIS 2 | F1153: EDP ALIANCA | G1153: BASICA | H1153: 525 | I1153: 440-525 kV | J1153: 150 | K1153: 2022-02-18 | L1153: 4.6 | M1153: não

Sheet Linhas_Mvar_km
A1: Carregamento capacitivo das linhas CA ativas (Mvar/km) por nível de tensão
A2: Fonte: ONS – Portal de Dados Abertos (dados.ons.org.br), acesso em 09/10/2026, licença cc-by. LINHA_TRANSMISSAO.csv; Mvar/km = val_shunt ÷ val_comprimento (val_shunt = susceptância de sequência positiva em Mvar, convenção ANAREDE).
A4: val_niveltensao_kv | B4: linhas | C4: km_total | D4: Mvar_carregamento_total | E4: Mvar_km_p10 | F4: Mvar_km_mediana | G4: Mvar_km_p90 | H4: comprimento_mediano_km | I4: comprimento_p90_km
A5: 230 | B5: 948 | C5: 70339.054 | D5: 15033.961 | E5: 0.167 | F5: 0.182 | G5: 0.264 | H5: 53.805 | I5: 163
A6: 345 | B6: 155 | C6: 11034.148 | D6: 7338.702 | E6: 0.509 | F6: 0.533 | G6: 0.775 | H6: 49 | I6: 177.804
A7: 440 | B7: 63 | C7: 7068.32 | D7: 7011.176 | E7: 0.932 | F7: 1.003 | G7: 1.032 | H7: 106.91 | I7: 220.8
A8: 500 | B8: 410 | C8: 70233.958 | D8: 110281.99 | E8: 1.167 | F8: 1.451 | G8: 2.134 | H8: 168.945 | I8: 342.071
A9: 525 | B9: 86 | C9: 12159.68 | D9: 17740.25 | E9: 1.325 | F9: 1.433 | G9: 1.581 | H9: 129.55 | I9: 263.75

Sheet Disp_FTRT_Estat
A1: Disponibilidade mensal das Funções Transmissão de Reator (FTRT), estatísticas 2011–2026
A2: Fonte: ONS – Portal de Dados Abertos (dados.ons.org.br), acesso em 09/10/2026, licença cc-by. IND_DISPONIBILIDADE_FT_REATIVO_2011..2026.csv (indicador DISP, Submódulo 9.2 dos Procedimentos de Rede).
A3: indisp_horas_mes = (100 − DISP)/100 × horas do mês. Agregado por nível de tensão, não por equipamento.
A4: caracteristica | B4: meses | C4: inicio | D4: fim | E4: disp_media | F4: disp_dp | G4: disp_min | H4: indisp_horas_mes_media | I4: indisp_horas_mes_p95
A5: FTRT - 230 | B5: 189 | C5: 2011-01-01 | D5: 2026-09-01 | E5: 98.448 | F5: 0.8331 | G5: 95.9258 | H5: 11.3385 | I5: 21.5212
A6: FTRT - 345 | B6: 189 | C6: 2011-01-01 | D6: 2026-09-01 | E6: 99.1675 | F6: 1.5143 | G6: 88.3616 | H6: 6.0689 | I6: 33.1141
A7: FTRT - 440 | B7: 189 | C7: 2011-01-01 | D7: 2026-09-01 | E7: 98.1595 | F7: 2.6744 | G7: 89.0194 | H7: 13.4077 | I7: 65.8361
A8: FTRT - 500 | B8: 189 | C8: 2011-01-01 | D8: 2026-09-01 | E8: 99.1008 | F8: 0.6671 | G8: 97.3459 | H8: 6.566 | I8: 16.489
A9: FTRT - 765 | B9: 189 | C9: 2011-01-01 | D9: 2026-09-01 | E9: 95.9412 | F9: 11.7674 | G9: 44.3715 | H9: 29.6485 | I9: 248.0005

Sheet Disp_FTRT_Anual
A1: Disponibilidade média anual das FTRT (%)
A2: Fonte: ONS – Portal de Dados Abertos (dados.ons.org.br), acesso em 09/10/2026, licença cc-by. IND_DISPONIBILIDADE_FT_REATIVO_*.csv.
A4: ano | B4: FTRT - 230 | C4: FTRT - 345 | D4: FTRT - 440 | E4: FTRT - 500 | F4: FTRT - 765
A5: 2011 | B5: 98.2006 | C5: 99.365 | D5: 98.8411 | E5: 99.6725 | F5: 99.89
A6: 2012 | B6: 98.527 | C6: 99.1759 | D6: 91.8516 | E6: 99.7361 | F6: 99.9648
A7: 2013 | B7: 98.6885 | C7: 98.6506 | D7: 98.0729 | E7: 99.7267 | F7: 99.8086
A8: 2014 | B8: 99.4918 | C8: 97.6926 | D8: 99.1936 | E8: 99.3171 | F8: 99.8871
A9: 2015 | B9: 99.3492 | C9: 99.6061 | D9: 96.1314 | E9: 99.3363 | F9: 99.9506
A10: 2016 | B10: 99.5433 | C10: 99.849 | D10: 98.6668 | E10: 99.7507 | F10: 99.7103
A11: 2017 | B11: 98.8496 | C11: 99.6296 | D11: 99.1916 | E11: 99.0787 | F11: 98.8714
A12: 2018 | B12: 98.7366 | C12: 99.5661 | D12: 99.1728 | E12: 98.9852 | F12: 65.4422
A13: 2019 | B13: 97.4494 | C13: 99.4244 | D13: 99.0771 | E13: 98.7936 | F13: 99.972
A14: 2020 | B14: 97.9527 | C14: 99.8318 | D14: 98.9841 | E14: 98.8658 | F14: 99.7355
A15: 2021 | B15: 98.0847 | C15: 99.837 | D15: 95.4664 | E15: 99.3453 | F15: 89.9472
A16: 2022 | B16: 97.8352 | C16: 99.7499 | D16: 99.7551 | E16: 99.539 | F16: 93.7852
... A20: 2026 | B20: 97.3905 | C20: 98.0871 | D20: 99.5705 | E20: 98.3524 | F20: 100

Sheet Disp_FT_Mensal
A1: Série mensal de disponibilidade de todas as FT de reativo (reator, capacitor, compensadores)
A2: Fonte: ONS – Portal de Dados Abertos (dados.ons.org.br), acesso em 09/10/2026, licença cc-by. IND_DISPONIBILIDADE_FT_REATIVO_*.csv.
A4: caracteristica | B4: data | C4: disp_pct | D4: tipo | E4: kv | F4: indisp_pct | G4: horas_indisp_mes
A5: FTBC - 13.8 | B5: 2011-01-01 | C5: 88.3455 | D5: FTBC | E5: 13.8 | F5: 11.6545 | G5: 86.70948
A6: FTBC - 13.8 | B6: 2011-02-01 | C6: 88.4059 | D6: FTBC | E6: 13.8 | F6: 11.5941 | G6: 77.912352
A7: FTBC - 13.8 | B7: 2011-03-01 | C7: 88.2582 | D7: FTBC | E7: 13.8 | F7: 11.7418 | G7: 87.358992
A8: FTBC - 13.8 | B8: 2011-04-01 | C8: 89.0536 | D8: FTBC | E8: 13.8 | F8: 10.9464 | G8: 78.81408
A9: FTBC - 13.8 | B9: 2011-05-01 | C9: 89.4124 | D9: FTBC | E9: 13.8 | F9: 10.5876 | G9: 78.771744
A10: FTBC - 13.8 | B10: 2011-06-01 | C10: 89.3885 | D10: FTBC | E10: 13.8 | F10: 10.6115 | G10: 76.4028
A11: FTBC - 13.8 | B11: 2011-07-01 | C11: 89.3081 | D11: FTBC | E11: 13.8 | F11: 10.6919 | G11: 79.547736
A12: FTBC - 13.8 | B12: 2011-08-01 | C12: 88.6973 | D12: FTBC | E12: 13.8 | F12: 11.3027 | G12: 84.092088
A13: FTBC - 13.8 | B13: 2011-09-01 | C13: 86.1646 | D13: FTBC | E13: 13.8 | F13: 13.8354 | G13: 99.61488
A14: FTBC - 13.8 | B14: 2011-10-01 | C14: 85.2027 | D14: FTBC | E14: 13.8 | F14: 14.7973 | G14: 110.09191
A15: FTBC - 13.8 | B15: 2011-11-01 | C15: 86.8121 | D15: FTBC | E15: 13.8 | F15: 13.1879 | G15: 94.95288
A16: FTBC - 13.8 | B16: 2011-12-01 | C16: 88.4252 | D16: FTBC | E16: 13.8 | F16: 11.5748 | G16: 86.116512
... A7328: FTRT - 765 | B7328: 2026-09-01 | C7328: 100 | D7328: FTRT | E7328: 765 | F7328: 0 | G7328: 0

Sheet CurvaPato_Estat
A1: Curva de pato: estatísticas diárias da carga líquida por subsistema (mai/2025–out/2026)
A2: Fonte: ONS – Portal de Dados Abertos (dados.ons.org.br), acesso em 09/10/2026, licença cc-by. BALANCO_DESSEM_DETALHE (499 arquivos diários, semi-horários). Carga líquida = demanda − (eólica + fotovoltaica + MMGD). Script: scripts/02_series_carga_curva_pato.py
A3: Valores em MW. Dados programados (DESSEM), não verificados. SIN = soma dos 4 subsistemas nos 465 dias completos. Carga líquida do NE pode ser negativa (exportador).
A4: cod_subsistema | B4: dias | C4: inicio | D4: fim | E4: amplitude_media | F4: amplitude_dp | G4: amplitude_p05 | H4: amplitude_p50 | I4: amplitude_p95 | J4: rampa3h_media | K4: rampa3h_p95 | L4: rampa3h_max | M4: vale_vs_media_media | N4: liquida_min_absoluta | O4: hora_min_moda | P4: pct_dias_min_entre_10e15h | Q4: cv_amplitude
A5: N | B5: 499 | C5: 2025-05-23 | D5: 2026-10-09 | E5: 2837.46 | F5: 567.94 | G5: 2205.88 | H5: 2728.79 | I5: 3797.21 | J5: 1484.01 | K5: 1914.62 | L5: 2406.79 | M5: 1607.75 | N5: 4345.78 | O5: 12 | P5: 98.8 | Q5: 0.2
A6: NE | B6: 499 | C6: 2025-05-23 | D6: 2026-10-09 | E6: 10626.84 | F6: 2667.97 | G6: 6990.64 | H6: 10214.61 | I6: 15277.61 | J6: 6813.11 | K6: 10524.12 | L6: 13754.26 | M6: 5120.63 | N6: -13459.71 | O6: 7.5 | P6: 7.01 | Q6: 0.25
A7: S | B7: 499 | C7: 2025-05-23 | D7: 2026-10-09 | E7: 7334.69 | F7: 1300.75 | G7: 5386.92 | H7: 7348.98 | I7: 9364.87 | J7: 4491.33 | K7: 6556.92 | L7: 9384.89 | M7: 3096.99 | N7: 1186.64 | O7: 12.5 | P7: 67.13 | Q7: 0.18
A8: SE | B8: 499 | C8: 2025-05-23 | D8: 2026-10-09 | E8: 24298.05 | F8: 4034.04 | G8: 17255.42 | H8: 24505.15 | I8: 30202.28 | J8: 15888.55 | K8: 22079.19 | L8: 26863.01 | M8: 11011.12 | N8: 12016.14 | O8: 12 | P8: 96.99 | Q8: 0.17
A9: SIN | B9: 465 | C9: 2025-05-23 | D9: 2026-10-09 | E9: 38100.2 | F9: 4162.53 | G9: 31958.6 | H9: 38067.79 | I9: 45251.49 | J9: 26545.28 | K9: 34758.4 | L9: 43044.64 | M9: 15795.35 | N9: 22030.87 | O9: 12 | P9: 92.69 | Q9: 0.11

Sheet CurvaPato_Mensal
A1: Curva de pato: médias mensais por subsistema
A2: Fonte: ONS – Portal de Dados Abertos (dados.ons.org.br), acesso em 09/10/2026, licença cc-by. BALANCO_DESSEM_DETALHE.
A4: cod_subsistema | B4: mes | C4: amplitude_media | D4: rampa3h_media | E4: liquida_min_media | F4: mmgd_pico_medio | G4: pct_dias_min_10a15h
A5: N | B5: 2025-05 | C5: 2500.1 | D5: 1421.9 | E5: 5960.7 | F5: 1929.4 | G5: 100
A6: N | B6: 2025-06 | C6: 2422 | D6: 1362 | E6: 5879.1 | F6: 1853.7 | G6: 100
A7: N | B7: 2025-07 | C7: 2537.2 | D7: 1356.6 | E7: 5770.8 | F7: 2009.9 | G7: 100
A8: N | B8: 2025-08 | C8: 2534.1 | D8: 1314.2 | E8: 6225.9 | F8: 1900.1 | G8: 87.1
A9: N | B9: 2025-09 | C9: 2749.6 | D9: 1517.7 | E9: 6379.2 | F9: 2144.9 | G9: 96.7
A10: N | B10: 2025-10 | C10: 2823.1 | D10: 1462.2 | E10: 6333.9 | F10: 2221.7 | G10: 100
A11: N | B11: 2025-11 | C11: 2761.3 | D11: 1396.7 | E11: 6538.7 | F11: 2033.7 | G11: 100
A12: N | B12: 2025-12 | C12: 2606.9 | D12: 1394.4 | E12: 6156.2 | F12: 1855.9 | G12: 100
A13: N | B13: 2026-01 | C13: 2606.3 | D13: 1301.7 | E13: 5861.4 | F13: 1853.3 | G13: 96.7
A14: N | B14: 2026-02 | C14: 2655.2 | D14: 1285.6 | E14: 5917.4 | F14: 1825.8 | G14: 100
A15: N | B15: 2026-03 | C15: 2679.4 | D15: 1351.4 | E15: 6095.6 | F15: 1783.4 | G15: 100
A16: N | B16: 2026-04 | C16: 2678.8 | D16: 1392.5 | E16: 6053.8 | F16: 1761.9 | G16: 100
... A94: SIN | B94: 2026-10 | C94: 38584.4 | D94: 27507.5 | E94: 40058.1 | F94: 32318 | G94: 75

Sheet CurvaPato_Diario
A1: Curva de pato: métricas diárias por subsistema (série para o modelo estocástico)
A2: Fonte: ONS – Portal de Dados Abertos (dados.ons.org.br), acesso em 09/10/2026, licença cc-by. BALANCO_DESSEM_DETALHE.
A4: cod_subsistema | B4: data | C4: demanda_media | D4: liquida_media | E4: liquida_min | F4: hora_liquida_min | G4: liquida_max | H4: hora_liquida_max | I4: amplitude_liquida | J4: vale_vs_media_dia | K4: rampa_max_3h | L4: descida_max_3h | M4: mmgd_pico | N4: fv_pico | O4: fracao_vre_no_vale | P4: variacao_semihoraria_dp | Q4: dia_semana | R4: fim_de_semana | S4: mes
A5: N | B5: 2025-05-23 | C5: 8118.8 | D5: 7466.69 | E5: 6131.23 | F5: 11.5 | G5: 8341.11 | H5: 22 | I5: 2209.88 | J5: 1335.46 | K5: 1237.18 | L5: -783.76 | M5: 1842 | N5: 4 | O5: 0.24 | P5: 122.35 | Q5: 4 | R5: não | S5: 2025-05
A6: N | B6: 2025-05-24 | C6: 7865.68 | D6: 7169.95 | E6: 5668.39 | F6: 12 | G6: 8241.01 | H6: 0 | I6: 2572.62 | J6: 1501.56 | K6: 1296.45 | L6: -1219.45 | M6: 1781 | N6: 4 | O6: 0.26 | P6: 138.94 | Q6: 5 | R6: sim | S6: 2025-05
A7: N | B7: 2025-05-25 | C7: 7628.74 | D7: 6915.68 | E7: 5111.41 | F7: 11 | G7: 8154.96 | H7: 22.5 | I7: 3043.55 | J7: 1804.27 | K7: 1626.61 | L7: -1673.06 | M7: 1861 | N7: 4 | O7: 0.28 | P7: 167.21 | Q7: 6 | R7: sim | S7: 2025-05
A8: N | B8: 2025-05-26 | C8: 8227.2 | D8: 7529.59 | E8: 6281.42 | F8: 12 | G8: 8502.05 | H8: 21.5 | I8: 2220.63 | J8: 1248.17 | K8: 1445.91 | L8: -667.01 | M8: 1848 | N8: 4 | O8: 0.24 | P8: 123.34 | Q8: 0 | R8: não | S8: 2025-05
A9: N | B9: 2025-05-27 | C9: 8306.22 | D9: 7546.6 | E9: 6188.05 | F9: 12 | G9: 8615.3 | H9: 22 | I9: 2427.25 | J9: 1358.55 | K9: 1500.87 | L9: -841.73 | M9: 1989 | N9: 4 | O9: 0.26 | P9: 132.17 | Q9: 1 | R9: não | S9: 2025-05
A10: N | B10: 2025-05-28 | C10: 8419.54 | D10: 7685.21 | E10: 6216.08 | F10: 12 | G10: 8809.08 | H10: 22.5 | I10: 2593 | J10: 1469.13 | K10: 1521.04 | L10: -881.86 | M10: 2089 | N10: 4 | O10: 0.26 | P10: 135.55 | Q10: 2 | R10: não | S10: 2025-05
A11: N | B11: 2025-05-29 | C11: 8313.32 | D11: 7588.55 | E11: 6207.93 | F11: 12 | G11: 8624.1 | H11: 22.5 | I11: 2416.17 | J11: 1380.62 | K11: 1527.99 | L11: -962.88 | M11: 2003 | N11: 4 | O11: 0.25 | P11: 136.82 | Q11: 3 | R11: não | S11: 2025-05
A12: N | B12: 2025-05-30 | C12: 8294.46 | D12: 7510.31 | E12: 6125.21 | F12: 12 | G12: 8455.13 | H12: 21.5 | I12: 2329.92 | J12: 1385.1 | K12: 1369.65 | L12: -910.82 | M12: 1961 | N12: 4 | O12: 0.26 | P12: 125.68 | Q12: 4 | R12: não | S12: 2025-05
A13: N | B13: 2025-05-31 | C13: 8102.16 | D13: 7306.07 | E13: 5716.16 | F13: 12 | G13: 8403.83 | H13: 0 | I13: 2687.67 | J13: 1589.91 | K13: 1271.82 | L13: -1233.66 | M13: 1991 | N13: 4 | O13: 0.28 | P13: 145.19 | Q13: 5 | R13: sim | S13: 2025-05
A14: N | B14: 2025-06-01 | C14: 7792.25 | D14: 7049 | E14: 5228.81 | F14: 10.5 | G14: 8338.26 | H14: 22 | I14: 3109.45 | J14: 1820.19 | K14: 1474.02 | L14: -1626.01 | M14: 1723 | N14: 4 | O14: 0.27 | P14: 165.01 | Q14: 6 | R14: sim | S14: 2025-06
A15: N | B15: 2025-06-02 | C15: 8274.12 | D15: 7544.79 | E15: 6352.25 | F15: 12 | G15: 8585.38 | H15: 22 | I15: 2233.13 | J15: 1192.54 | K15: 1325.38 | L15: -676.35 | M15: 1839 | N15: 4 | O15: 0.24 | P15: 120.4 | Q15: 0 | R15: não | S15: 2025-06
A16: N | B16: 2025-06-03 | C16: 8271.95 | D16: 7490.29 | E16: 6266.23 | F16: 12 | G16: 8450.41 | H16: 22 | I16: 2184.18 | J16: 1224.06 | K16: 1334 | L16: -711.13 | M16: 1876 | N16: 4 | O16: 0.25 | P16: 120.22 | Q16: 1 | R16: não | S16: 2025-06
... A107: N | B107: 2025-09-02 | C107: 8665.73 | D107: 7694.58 | E107: 6330.62 | F107: 12 | G107: 8821.6 | H107: 22.5 | I107: 2490.98 | J107: 1363.96 | K107: 1482.81 | L107: -1021.29 | M107: 2202 | N107: 4 | O107: 0.27 | P107: 145.68 | Q107: 1 | R107: não | S107: 2025-09
A108: N | B108: 2025-09-03 | C108: 9233.63 | D108: 8835.88 | E108: 8757.43 | F108: 23.5 | G108: 8888.77 | H108: 22.5 | I108: 131.34 | J108: 78.45 | M108: 0 | N108: 0 | O108: 0.04 | P108: 52.76 | Q108: 2 | R108: não | S108: 2025-09
A109: N | B109: 2025-09-04 | C109: 8792.98 | D109: 7885.75 | E109: 6455.51 | F109: 12 | G109: 8995.55 | H109: 22 | I109: 2540.04 | J109: 1430.24 | K109: 1514 | L109: -1052.98 | M109: 2198 | N109: 4 | O109: 0.27 | P109: 144.89 | Q109: 3 | R109: não | S109: 2025-09
A110: N | B110: 2025-09-05 | C110: 8764.16 | D110: 7837.58 | E110: 6395.44 | F110: 12 | G110: 8848.08 | H110: 21.5 | I110: 2452.64 | J110: 1442.14 | K110: 1521.15 | L110: -1077.16 | M110: 2232 | N110: 4 | O110: 0.27 | P110: 147.53 | Q110: 4 | R110: não | S110: 2025-09
A111: N | B111: 2025-09-06 | C111: 8373.51 | D111: 7410.19 | E111: 5749.3 | F111: 12 | G111: 8639.78 | H111: 0 | I111: 2890.48 | J111: 1660.89 | K111: 1470.18 | L111: -1449.46 | M111: 2226 | N111: 4 | O111: 0.3 | P111: 155.06 | Q111: 5 | R111: sim | S111: 2025-09
A112: N | B112: 2025-09-07 | C112: 7925.25 | D112: 6776.22 | E112: 5070.85 | F112: 11.5 | G112: 8597 | H112: 23 | I112: 3526.15 | J112: 1705.37 | K112: 1584.16 | L112: -2168.74 | M112: 2177 | N112: 4 | O112: 0.32 | P112: 236.17 | Q112: 6 | R112: sim | S112: 2025-09
A113: N | B113: 2025-09-08 | C113: 8544.95 | D113: 7647.58 | E113: 6237.48 | F113: 12 | G113: 8855.67 | H113: 22 | I113: 2618.19 | J113: 1410.1 | K113: 1488.97 | L113: -894.82 | M113: 2198 | N113: 4 | O113: 0.27 | P113: 131.05 | Q113: 0 | R113: não | S113: 2025-09
A114: N | B114: 2025-09-09 | C114: 8550.11 | D114: 7574.17 | E114: 6062.72 | F114: 12 | G114: 8741.42 | H114: 21.5 | I114: 2678.7 | J114: 1511.45 | K114: 1374.92 | L114: -1106.15 | M114: 2227 | N114: 4 | O114: 0.29 | P114: 141.49 | Q114: 1 | R114: não | S114: 2025-09
A115: N | B115: 2025-09-10 | C115: 8564.72 | D115: 7354.88 | E115: 6059.74 | F115: 12 | G115: 8688.85 | H115: 0 | I115: 2629.11 | J115: 1295.14 | K115: 1564.79 | L115: -1157.01 | M115: 2284 | N115: 4 | O115: 0.29 | P115: 164.61 | Q115: 2 | R115: não | S115: 2025-09
A116: N | B116: 2025-09-11 | C116: 8841.73 | D116: 7839.5 | E116: 6331.48 | F116: 12 | G116: 9109.61 | H116: 22 | I116: 2778.13 | J116: 1508.02 | K116: 1704.65 | L116: -1064.09 | M116: 2259 | N116: 4 | O116: 0.28 | P116: 150.43 | Q116: 3 | R116: não | S116: 2025-09
A117: N | B117: 2025-09-12 | C117: 8777.33 | D117: 7587.45 | E117: 6625.55 | F117: 10.5 | G117: 8882.86 | H117: 0 | I117: 2257.31 | J117: 961.9 | K117: 1641.04 | L117: -1039.92 | M117: 2040 | N117: 4 | O117: 0.25 | P117: 164.37 | Q117: 4 | R117: não | S117: 2025-09
A118: N | B118: 2025-09-13 | C118: 8777.1 | D118: 7849.12 | E118: 6284.19 | F118: 12 | G118: 9150.75 | H118: 22 | I118: 2866.56 | J118: 1564.93 | K118: 1304.16 | L118: -1314.2 | M118: 1977 | N118: 4 | O118: 0.26 | P118: 156.47 | Q118: 5 | R118: sim | S118: 2025-09
A119: N | B119: 2025-09-14 | C119: 8448.44 | D119: 7464.5 | E119: 5323.87 | F119: 11 | G119: 9140.15 | H119: 23 | I119: 3816.28 | J119: 2140.63 | K119: 1555.95 | L119: -1897.85 | M119: 2154 | N119: 4 | O119: 0.31 | P119: 188.43 | Q119: 6 | R119: sim | S119: 2025-09
A120: N | B120: 2025-09-15 | C120: 8760.91 | D120: 7774.54 | E120: 6398.44 | F120: 12 | G120: 9093.42 | H120: 22.5 | I120: 2694.98 | J120: 1376.1 | K120: 1484.15 | L120: -956.71 | M120: 2244 | N120: 4 | O120: 0.28 | P120: 140.27 | Q120: 0 | R120: não | S120: 2025-09
... A235: N | B235: 2026-01-08 | C235: 8302.15 | D235: 7210.15 | E235: 5843.52 | F235: 12 | G235: 8360.75 | H235: 0 | I235: 2517.23 | J235: 1366.63 | K235: 1393.69 | L235: -840.8 | M235: 1960 | N235: 3 | O235: 0.27 | P235: 146.91 | Q235: 3 | R235: não | S235: 2026-01
A236: N | B236: 2026-01-09 | C236: 8700.36 | D236: 8350.12 | E236: 8329.31 | F236: 22 | G236: 8396.27 | H236: 23.5 | I236: 66.96 | J236: 20.81 | M236: 0 | N236: 0 | O236: 0.04 | P236: 34.21 | Q236: 4 | R236: não | S236: 2026-01
A237: N | B237: 2026-01-10 | C237: 8066.74 | D237: 7077.8 | E237: 5284.85 | F237: 12 | G237: 8317.88 | H237: 0 | I237: 3033.03 | J237: 1792.95 | K237: 1201.07 | L237: -1409.79 | M237: 2146 | N237: 3 | O237: 0.32 | P237: 151.15 | Q237: 5 | R237: sim | S237: 2026-01
A238: N | B238: 2026-01-11 | C238: 7700.97 | D238: 6773.3 | E238: 4957.43 | F238: 11.5 | G238: 8078.75 | H238: 23 | I238: 3121.32 | J238: 1815.87 | K238: 1337.83 | L238: -1570.88 | M238: 1942 | N238: 3 | O238: 0.31 | P238: 159.04 | Q238: 6 | R238: sim | S238: 2026-01
A239: N | B239: 2026-01-12 | C239: 8371.82 | D239: 7427.73 | E239: 6112.52 | F239: 12 | G239: 8603.19 | H239: 22.5 | I239: 2490.67 | J239: 1315.21 | K239: 1351.93 | L239: -748.44 | M239: 1987 | N239: 3 | O239: 0.27 | P239: 122.75 | Q239: 0 | R239: não | S239: 2026-01
A240: N | B240: 2026-01-13 | C240: 8416 | D240: 7536.4 | E240: 6289.6 | F240: 10.5 | G240: 8627.36 | H240: 22.5 | I240: 2337.76 | J240: 1246.8 | K240: 1027.79 | L240: -967.42 | M240: 1776 | N240: 3 | O240: 0.25 | P240: 115.21 | Q240: 1 | R240: não | S240: 2026-01
A241: N | B241: 2026-01-14 | C241: 8208.94 | D241: 7253.46 | E241: 5903.28 | F241: 12 | G241: 8391.13 | H241: 22.5 | I241: 2487.85 | J241: 1350.18 | K241: 1337.64 | L241: -848.12 | M241: 1904 | N241: 3 | O241: 0.27 | P241: 127.51 | Q241: 2 | R241: não | S241: 2026-01
A242: N | B242: 2026-01-15 | C242: 8301.17 | D242: 7401.36 | E242: 6064.1 | F242: 12 | G242: 8444.04 | H242: 22.5 | I242: 2379.94 | J242: 1337.26 | K242: 1299.16 | L242: -876.6 | M242: 1880 | N242: 3 | O242: 0.26 | P242: 122.56 | Q242: 3 | R242: não | S242: 2026-01
A243: N | B243: 2026-01-16 | C243: 8256.52 | D243: 7368.96 | E243: 5882.1 | F243: 12 | G243: 8509.17 | H243: 23 | I243: 2627.07 | J243: 1486.86 | K243: 1240.28 | L243: -914.22 | M243: 1944 | N243: 3 | O243: 0.27 | P243: 123.31 | Q243: 4 | R243: não | S243: 2026-01
A244: N | B244: 2026-01-17 | C244: 8082.69 | D244: 7294.08 | E244: 5759.74 | F244: 12 | G244: 8414 | H244: 0 | I244: 2654.26 | J244: 1534.34 | K244: 1036.39 | L244: -1148 | M244: 1841 | N244: 3 | O244: 0.27 | P244: 130.98 | Q244: 5 | R244: sim | S244: 2026-01
A245: N | B245: 2026-01-18 | C245: 7859.99 | D245: 7092.32 | E245: 5272.48 | F245: 11.5 | G245: 8368.96 | H245: 23 | I245: 3096.48 | J245: 1819.84 | K245: 1391.63 | L245: -1535.53 | M245: 1778 | N245: 3 | O245: 0.28 | P245: 156.72 | Q245: 6 | R245: sim | S245: 2026-01
...

Sheet Perfil_Mes_Hora
A1: Perfil médio da carga líquida por mês e meia-hora (MW) – as curvas de pato
A2: Fonte: ONS – Portal de Dados Abertos (dados.ons.org.br), acesso em 09/10/2026, licença cc-by. BALANCO_DESSEM_DETALHE.
A4: cod_subsistema | B4: mes | C4: hora | D4: liquida
A5: N | B5: 2025-05 | C5: 0 | D5: 8291
A6: N | B6: 2025-05 | C6: 0.5 | D6: 8203
A7: N | B7: 2025-05 | C7: 1 | D7: 8119
A8: N | B8: 2025-05 | C8: 1.5 | D8: 8033
A9: N | B9: 2025-05 | C9: 2 | D9: 7953
A10: N | B10: 2025-05 | C10: 2.5 | D10: 7859
A11: N | B11: 2025-05 | C11: 3 | D11: 7770
A12: N | B12: 2025-05 | C12: 3.5 | D12: 7693
A13: N | B13: 2025-05 | C13: 4 | D13: 7627
A14: N | B14: 2025-05 | C14: 4.5 | D14: 7587
A15: N | B15: 2025-05 | C15: 5 | D15: 7569
A16: N | B16: 2025-05 | C16: 5.5 | D16: 7502
... A4324: SIN | B4324: 2026-10 | C4324: 23.5 | D4324: 63029

Sheet Carga_Anual
A1: Carga horária 2015–2026: estatísticas anuais por subsistema
A2: Fonte: ONS – Portal de Dados Abertos (dados.ons.org.br), acesso em 09/10/2026, licença cc-by. CURVA_CARGA_2015..2026.csv (carga de energia horária, MWmed). Script: scripts/02_series_carga_curva_pato.py
A3: 2026 parcial (até 07/10/2026). fator_carga = média/máximo diário. pct_dias_min_10a15h = % de dias cujo mínimo horário ocorre entre 10h e 15h.
A4: id_subsistema | B4: ano | C4: carga_media | D4: amplitude_media | E4: amplitude_p95 | F4: fator_carga | G4: rampa3h_media | H4: pct_dias_min_10a15h | I4: dias
A5: N | B5: 2015 | C5: 5220.2 | D5: 1111.5 | E5: 1416.7 | F5: 0.9 | G5: 725.1 | H5: 5.2 | I5: 364
A6: N | B6: 2016 | C6: 5330.1 | D6: 1149.9 | E6: 1444 | F6: 0.9 | G6: 715.4 | H6: 10.1 | I6: 366
A7: N | B7: 2017 | C7: 5421.3 | D7: 1117.7 | E7: 1413 | F7: 0.9 | G7: 682 | H7: 7.4 | I7: 365
A8: N | B8: 2018 | C8: 5300.7 | D8: 1145.1 | E8: 1450.5 | F8: 0.9 | G8: 700.3 | H8: 8.5 | I8: 365
A9: N | B9: 2019 | C9: 5500 | D9: 1137.3 | E9: 1440.9 | F9: 0.9 | G9: 668.5 | H9: 9.3 | I9: 365
A10: N | B10: 2020 | C10: 5516.8 | D10: 1226 | E10: 2175.3 | F10: 0.9 | G10: 634.1 | H10: 14.5 | I10: 366
A11: N | B11: 2021 | C11: 5986.1 | D11: 1147.1 | E11: 1469.7 | F11: 0.9 | G11: 588.2 | H11: 17 | I11: 365
A12: N | B12: 2022 | C12: 6214 | D12: 1281.8 | E12: 1754 | F12: 0.9 | G12: 696.2 | H12: 25.5 | I12: 365
A13: N | B13: 2023 | C13: 7140.1 | D13: 1378.7 | E13: 1821.3 | F13: 0.9 | G13: 756.4 | H13: 20 | I13: 365
A14: N | B14: 2024 | C14: 7819.8 | D14: 1423.2 | E14: 1852.1 | F14: 0.9 | G14: 742.5 | H14: 5.7 | I14: 366
A15: N | B15: 2025 | C15: 8311.7 | D15: 1437.2 | E15: 1859.6 | F15: 0.9 | G15: 760.9 | H15: 3.6 | I15: 365
A16: N | B16: 2026 | C16: 8663.5 | D16: 1613.3 | E16: 2327.4 | F16: 0.9 | G16: 859.4 | H16: 10.7 | I16: 280
... A64: SIN | B64: 2026 | C64: 80525.2 | D64: 23871.6 | E64: 29270.7 | F64: 0.9 | G64: 12381.6 | H64: 1.4 | I64: 280

Sheet Carga_Diaria
A1: Carga horária 2015–2026: métricas diárias por subsistema
A2: Fonte: ONS – Portal de Dados Abertos (dados.ons.org.br), acesso em 09/10/2026, licença cc-by. CURVA_CARGA_2015..2026.csv.
A4: id_subsistema | B4: data | C4: media | D4: minimo | E4: hora_min | F4: maximo | G4: hora_max | H4: amplitude | I4: fator_carga | J4: rampa_max_3h | K4: horas
A5: N | B5: 2015-01-01 | C5: 4541 | D5: 4172.7 | E5: 14 | F5: 5081.4 | G5: 23 | H5: 908.7 | I5: 0.9 | J5: 813.2 | K5: 24
A6: N | B6: 2015-01-02 | C6: 4886.8 | D6: 4371.3 | E6: 7 | F6: 5330.4 | G6: 23 | H6: 959.1 | I6: 0.9 | J6: 461 | K6: 24
A7: N | B7: 2015-01-03 | C7: 4856.1 | D7: 4462.8 | E7: 8 | F7: 5293.9 | G7: 21 | H7: 831.1 | I7: 0.9 | J7: 681.6 | K7: 24
A8: N | B8: 2015-01-04 | C8: 4618.2 | D8: 4191.5 | E8: 8 | F8: 5193 | G8: 0 | H8: 1001.5 | I8: 0.9 | J8: 702.1 | K8: 24
A9: N | B9: 2015-01-05 | C9: 4876.8 | D9: 4343.4 | E9: 7 | F9: 5248.9 | G9: 23 | H9: 905.5 | I9: 0.9 | J9: 557.2 | K9: 24
A10: N | B10: 2015-01-06 | C10: 5033 | D10: 4413.7 | E10: 7 | F10: 5514.8 | G10: 15 | H10: 1101.2 | I10: 0.9 | J10: 715.8 | K10: 24
A11: N | B11: 2015-01-07 | C11: 5113.5 | D11: 4458.5 | E11: 7 | F11: 5548.7 | G11: 16 | H11: 1090.3 | I11: 0.9 | J11: 707.2 | K11: 24
A12: N | B12: 2015-01-08 | C12: 5223.5 | D12: 4552.4 | E12: 7 | F12: 5670.8 | G12: 16 | H12: 1118.4 | I12: 0.9 | J12: 709.1 | K12: 24
A13: N | B13: 2015-01-09 | C13: 5164.7 | D13: 4630.5 | E13: 7 | F13: 5482.7 | G13: 0 | H13: 852.2 | I13: 0.9 | J13: 622.9 | K13: 24
A14: N | B14: 2015-01-10 | C14: 4888.6 | D14: 4373.9 | E14: 8 | F14: 5311.1 | G14: 0 | H14: 937.2 | I14: 0.9 | J14: 582.9 | K14: 24
A15: N | B15: 2015-01-11 | C15: 4588.1 | D15: 4163.1 | E15: 17 | F15: 5091 | G15: 0 | H15: 927.9 | I15: 0.9 | J15: 778.7 | K15: 24
A16: N | B16: 2015-01-12 | C16: 5112.7 | D16: 4458.2 | E16: 7 | F16: 5658.2 | G16: 16 | H16: 1199.9 | I16: 0.9 | J16: 804.4 | K16: 24
... A293: N | B293: 2015-10-17 | C293: 5655 | D293: 4990.7 | E293: 7 | F293: 6181.6 | G293: 21 | H293: 1190.9 | I293: 0.9 | J293: 642.5 | K293: 24
A294: N | B294: 2015-10-18 | E294: 0 | G294: 0 | J294: 875.6 | K294: 24
A295: N | B295: 2015-10-19 | C295: 5805.9 | D295: 5062 | E295: 8 | F295: 6329.6 | G295: 15 | H295: 1267.6 | I295: 0.9 | J295: 793.9 | K295: 24
A296: N | B296: 2015-10-20 | C296: 5657.3 | D296: 4826.2 | E296: 7 | F296: 6287.9 | G296: 23 | H296: 1461.7 | I296: 0.9 | J296: 815.6 | K296: 24
A297: N | B297: 2015-10-21 | C297: 5837.6 | D297: 4909.5 | E297: 7 | F297: 6440.9 | G297: 15 | H297: 1531.4 | I297: 0.9 | J297: 989.7 | K297: 24
A298: N | B298: 2015-10-22 | C298: 5776 | D298: 4932.1 | E298: 8 | F298: 6263.7 | G298: 0 | H298: 1331.7 | I298: 0.9 | J298: 887.1 | K298: 24
A299: N | B299: 2015-10-23 | C299: 5765.3 | D299: 4913.8 | E299: 7 | F299: 6224.8 | G299: 16 | H299: 1311 | I299: 0.9 | J299: 836.2 | K299: 24
A300: N | B300: 2015-10-24 | C300: 5371.6 | D300: 4793.2 | E300: 8 | F300: 6049.9 | G300: 0 | H300: 1256.7 | I300: 0.9 | J300: 613.5 | K300: 24
A301: N | B301: 2015-10-25 | C301: 5044.4 | D301: 4162.1 | E301: 12 | F301: 5698.9 | G301: 0 | H301: 1536.8 | I301: 0.9 | J301: 701.3 | K301: 24
A302: N | B302: 2015-10-26 | C302: 5384 | D302: 4616.8 | E302: 7 | F302: 5862 | G302: 23 | H302: 1245.2 | I302: 0.9 | J302: 736.1 | K302: 24
A303: N | B303: 2015-10-27 | C303: 5468.8 | D303: 4615.4 | E303: 7 | F303: 5983.2 | G303: 15 | H303: 1367.8 | I303: 0.9 | J303: 873.3 | K303: 24
A304: N | B304: 2015-10-28 | C304: 5411.2 | D304: 4618.9 | E304: 7 | F304: 5898.3 | G304: 15 | H304: 1279.5 | I304: 0.9 | J304: 815.1 | K304: 24
A305: N | B305: 2015-10-29 | C305: 5361 | D305: 4609.2 | E305: 7 | F305: 5802.6 | G305: 23 | H305: 1193.4 | I305: 0.9 | J305: 758.2 | K305: 24
A306: N | B306: 2015-10-30 | C306: 5333.6 | D306: 4589.6 | E306: 8 | F306: 5795.5 | G306: 23 | H306: 1205.9 | I306: 0.9 | J306: 741.7 | K306: 24
... A657: N | B657: 2016-10-15 | C657: 5497.7 | D657: 4870.1 | E657: 7 | F657: 5980.2 | G657: 22 | H657: 1110.1 | I657: 0.9 | J657: 647.1 | K657: 24
A658: N | B658: 2016-10-16 | E658: 0 | G658: 0 | J658: 729.8 | K658: 24
A659: N | B659: 2016-10-17 | C659: 5782.7 | D659: 4950.7 | E659: 7 | F659: 6389.1 | G659: 15 | H659: 1438.3 | I659: 0.9 | J659: 689.6 | K659: 24
A660: N | B660: 2016-10-18 | C660: 5761.3 | D660: 4870.7 | E660: 7 | F660: 6270.8 | G660: 16 | H660: 1400.1 | I660: 0.9 | J660: 819.4 | K660: 24
A661: N | B661: 2016-10-19 | C661: 5751.2 | D661: 4897.1 | E661: 7 | F661: 6289 | G661: 23 | H661: 1391.9 | I661: 0.9 | J661: 756.6 | K661: 24
A662: N | B662: 2016-10-20 | C662: 5826.7 | D662: 5041.2 | E662: 8 | F662: 6237.6 | G662: 16 | H662: 1196.4 | I662: 0.9 | J662: 809.5 | K662: 24
A663: N | B663: 2016-10-21 | C663: 5763.8 | D663: 4984.6 | E663: 7 | F663: 6162.3 | G663: 0 | H663: 1177.7 | I663: 0.9 | J663: 819.5 | K663: 24
A664: N | B664: 2016-10-22 | C664: 5424.6 | D664: 4940.6 | E664: 8 | F664: 6003.5 | G664: 0 | H664: 1062.9 | I664: 0.9 | J664: 611.4 | K664: 24
A665: N | B665: 2016-10-23 | C665: 4935.7 | D665: 4106.5 | E665: 16 | F665: 5585.6 | G665: 0 | H665: 1479.1 | I665: 0.9 | J665: 1052.8 | K665: 24
A666: N | B666: 2016-10-24 | C666: 5160.4 | D666: 4606 | E666: 8 | F666: 5560.7 | G666: 22 | H666: 954.7 | I666: 0.9 | J666: 450.1 | K666: 24
A667: N | B667: 2016-10-25 | C667: 5486.9 | D667: 4615.9 | E667: 7 | F667: 6064.3 | G667: 15 | H667: 1448.3 | I667: 0.9 | J667: 817.7 | K667: 24
...

Sheet MMGD_Anual
A1: MMGD: potência adicionada e acumulada por ano (GW)
A2: Fonte: ANEEL – Portal de Dados Abertos (dadosabertos.aneel.gov.br), acesso em 09/10/2026, licença ODbL. Relação de empreendimentos de geração distribuída (período de referência 10/2026). Script: scripts/03_mmgd_aneel.py
A3: Data usada: DthAtualizaCadastralEmpreend (única data da base; proxy da data de conexão). Meses finais podem estar incompletos por atraso de registro. Registros com data 1900 (0,001 GW) excluídos.
A4: ano | B4: GW_adicionados | C4: GW_acumulado | D4: cresc_estoque_pct
A5: 2012 | B5: 0.001 | C5: 0.002 | D5: 100
A6: 2013 | B6: 0.001 | C6: 0.003 | D6: 50
A7: 2014 | B7: 0.004 | C7: 0.007 | D7: 133.3
A8: 2015 | B8: 0.015 | C8: 0.022 | D8: 214.3
A9: 2016 | B9: 0.075 | C9: 0.097 | D9: 340.9
A10: 2017 | B10: 0.178 | C10: 0.275 | D10: 183.5
A11: 2018 | B11: 0.463 | C11: 0.738 | D11: 168.4
A12: 2019 | B12: 1.724 | C12: 2.462 | D12: 233.6
A13: 2020 | B13: 3.461 | C13: 5.923 | D13: 140.6
A14: 2021 | B14: 5.659 | C14: 11.582 | D14: 95.5
A15: 2022 | B15: 8.869 | C15: 20.451 | D15: 76.6
A16: 2023 | B16: 8.737 | C16: 29.188 | D16: 42.7
... A19: 2026 | B19: 4.432 | C19: 53.876 | D19: 9

Sheet MMGD_Mensal_Regiao
A1: MMGD: estoque acumulado mensal por região (GW)
A2: Fonte: ANEEL – Portal de Dados Abertos (dadosabertos.aneel.gov.br), acesso em 09/10/2026, licença ODbL. Relação de empreendimentos de geração distribuída.
A4: mes | B4: Centro Oeste | C4: Nordeste | D4: Norte | E4: Sudeste | F4: Sul | G4: Brasil
A5: 2012-01 | B5: 0 | C5: 0 | D5: 0 | E5: 0.001 | F5: 0 | G5: 0.001
A6: 2012-02 | B6: 0 | C6: 0 | D6: 0 | E6: 0.001 | F6: 0 | G6: 0.002
A7: 2012-03 | B7: 0 | C7: 0 | D7: 0 | E7: 0.001 | F7: 0 | G7: 0.002
A8: 2012-06 | B8: 0 | C8: 0 | D8: 0 | E8: 0.001 | F8: 0 | G8: 0.002
A9: 2012-07 | B9: 0 | C9: 0 | D9: 0 | E9: 0.001 | F9: 0 | G9: 0.002
A10: 2012-09 | B10: 0 | C10: 0 | D10: 0 | E10: 0.001 | F10: 0 | G10: 0.002
A11: 2012-10 | B11: 0 | C11: 0 | D11: 0 | E11: 0.001 | F11: 0 | G11: 0.002
A12: 2012-11 | B12: 0 | C12: 0 | D12: 0 | E12: 0.001 | F12: 0 | G12: 0.002
A13: 2012-12 | B13: 0 | C13: 0 | D13: 0 | E13: 0.001 | F13: 0 | G13: 0.002
A14: 2013-02 | B14: 0 | C14: 0 | D14: 0 | E14: 0.001 | F14: 0 | G14: 0.002
A15: 2013-03 | B15: 0 | C15: 0 | D15: 0 | E15: 0.001 | F15: 0 | G15: 0.002
A16: 2013-04 | B16: 0 | C16: 0 | D16: 0 | E16: 0.001 | F16: 0 | G16: 0.002
... A176: 2026-08 | B176: 8.097 | C176: 11.038 | D176: 4.152 | E176: 17.399 | F176: 13.188 | G176: 53.874

Sheet MMGD_UF
A1: MMGD: estoque por UF
A2: Fonte: ANEEL – Portal de Dados Abertos (dadosabertos.aneel.gov.br), acesso em 09/10/2026, licença ODbL. Relação de empreendimentos de geração distribuída.
A4: SigUF | B4: qtd | C4: GW
A5: SP | B5: 783581 | C5: 7.578
A6: PR | B6: 335744 | C6: 6.898
A7: MG | B7: 484960 | C7: 6.469
A8: RS | B8: 427871 | C8: 3.957
A9: MT | B9: 238979 | C9: 3.181
A10: BA | B10: 326643 | C10: 2.966
A11: GO | B11: 186778 | C11: 2.432
A12: SC | B12: 199737 | C12: 2.332
A13: RJ | B13: 201287 | C13: 1.979
A14: MS | B14: 175109 | C14: 1.894
A15: CE | B15: 152724 | C15: 1.824
A16: PA | B16: 162478 | C16: 1.673
... A31: RR | B31: 8897 | C31: 0.121

Sheet MMGD_Distribuidora
A1: MMGD: estoque por distribuidora
A2: Fonte: ANEEL – Portal de Dados Abertos (dadosabertos.aneel.gov.br), acesso em 09/10/2026, licença ODbL. Relação de empreendimentos de geração distribuída.
A4: SigAgente | B4: qtd | C4: GW
A5: COPEL-DIS | B5: 329727 | C5: 6.822
A6: CEMIG-D | B6: 426729 | C6: 5.84
A7: EMT | B7: 238881 | C7: 3.18
A8: CPFL-PAULISTA | B8: 324388 | C8: 3.058
A9: COELBA | B9: 327227 | C9: 2.97
A10: RGE SUL | B10: 312490 | C10: 2.749
A11: EQUATORIAL GO | B11: 182805 | C11: 2.394
A12: CELESC | B12: 180852 | C12: 2.065
A13: ENEL CE | B13: 152766 | C13: 1.825
A14: EMS | B14: 165094 | C14: 1.805
A15: EQUATORIAL PA | B15: 162114 | C15: 1.674
A16: ELEKTRO | B16: 183993 | C16: 1.619
... A106: CODESAM | B106: 20 | C106: 0

Sheet Macro_Mensal
A1: Séries macroeconômicas mensais (IPCA, Selic, IGP-M, câmbio)
A2: Fonte: Banco Central do Brasil – SGS (api.bcb.gov.br), acesso em 09/10/2026. SGS 433 (IPCA), 4390 (Selic acumulada no mês), 189 (IGP-M), 3698 (US$ venda, média mensal), 21619 (€ venda, diário → média mensal). Script: scripts/04_custos_bpr_macro.py
A3: ipca_indice_base_dez2009 = produto acumulado de (1 + IPCA mensal), base dez/2009 = 1. Taxas em % (não em fração).
A4: mes | B4: ipca_mes_pct | C4: ipca_indice_base_dez2009 | D4: selic_mes_pct | E4: usd_brl_media | F4: igpm_mes_pct | G4: eur_brl_media | H4: ipca_12m_pct | I4: selic_12m_pct | J4: juro_real_12m_pct
A5: 2010-01 | B5: 0.75 | C5: 1.0075 | D5: 0.66 | E5: 1.7798 | F5: 0.63
A6: 2010-02 | B6: 0.78 | C6: 1.0154 | D6: 0.59 | E6: 1.8416 | F6: 1.18
A7: 2010-03 | B7: 0.52 | C7: 1.0206 | D7: 0.76 | E7: 1.7858 | F7: 0.94
A8: 2010-04 | B8: 0.57 | C8: 1.0265 | D8: 0.67 | E8: 1.7566 | F8: 0.77
A9: 2010-05 | B9: 0.43 | C9: 1.0309 | D9: 0.75 | E9: 1.8132 | F9: 1.19
A10: 2010-06 | B10: 0 | C10: 1.0309 | D10: 0.79 | E10: 1.8065 | F10: 0.85
A11: 2010-07 | B11: 0.01 | C11: 1.031 | D11: 0.86 | E11: 1.7696 | F11: 0.15
A12: 2010-08 | B12: 0.04 | C12: 1.0314 | D12: 0.89 | E12: 1.7596 | F12: 0.77
A13: 2010-09 | B13: 0.45 | C13: 1.036 | D13: 0.85 | E13: 1.7187 | F13: 1.15
A14: 2010-10 | B14: 0.75 | C14: 1.0438 | D14: 0.81 | E14: 1.6835 | F14: 1.01
A15: 2010-11 | B15: 0.83 | C15: 1.0525 | D15: 0.81 | E15: 1.7133 | F15: 1.45
A16: 2010-12 | B16: 0.63 | C16: 1.0591 | D16: 0.93 | E16: 1.6934 | F16: 0.69 | H16: 5.9091 | I16: 9.7825 | J16: 3.6573
A17: 2011-01 | B17: 0.83 | C17: 1.0679 | D17: 0.86 | E17: 1.6749 | F17: 0.79 | H17: 5.9932 | I17: 10.0006 | J17: 3.7808
A18: 2011-02 | B18: 0.8 | C18: 1.0764 | D18: 0.84 | E18: 1.668 | F18: 1 | H18: 6.0142 | I18: 10.274 | J18: 4.0181
A19: 2011-03 | B19: 0.79 | C19: 1.0849 | D19: 0.92 | E19: 1.6591 | F19: 0.62 | H19: 6.299 | I19: 10.4491 | J19: 3.9042
A20: 2011-04 | B20: 0.77 | C20: 1.0933 | D20: 0.84 | E20: 1.5864 | F20: 0.45 | H20: 6.5104 | I20: 10.6356 | J20: 3.8731
A21: 2011-05 | B21: 0.47 | C21: 1.0984 | D21: 0.99 | E21: 1.6135 | F21: 0.43 | H21: 6.5528 | I21: 10.8991 | J21: 4.0791
A22: 2011-06 | B22: 0.15 | C22: 1.1001 | D22: 0.96 | E22: 1.587 | F22: -0.18 | H22: 6.7126 | I22: 11.0862 | J22: 4.0985
A23: 2011-07 | B23: 0.16 | C23: 1.1018 | D23: 0.97 | E23: 1.5639 | F23: -0.12 | H23: 6.8727 | I23: 11.2073 | J23: 4.0559
A24: 2011-08 | B24: 0.37 | C24: 1.1059 | D24: 1.07 | E24: 1.597 | F24: 0.44 | H24: 7.2252 | I24: 11.4058 | J24: 3.8989
A25: 2011-09 | B25: 0.53 | C25: 1.1118 | D25: 0.94 | E25: 1.7498 | F25: 0.65 | H25: 7.3106 | I25: 11.5052 | J25: 3.9088
A26: 2011-10 | B26: 0.43 | C26: 1.1165 | D26: 0.88 | E26: 1.7726 | F26: 0.53 | H26: 6.9698 | I26: 11.5826 | J26: 4.3123
A27: 2011-11 | B27: 0.52 | C27: 1.1224 | D27: 0.86 | E27: 1.7905 | F27: 0.5 | H27: 6.6409 | I27: 11.6379 | J27: 4.6859
... A76: 2015-12 | B76: 0.96 | C76: 1.489 | D76: 1.16 | E76: 3.8711 | F76: 0.49 | H76: 10.6735 | I76: 13.2858 | J76: 2.3604
A77: 2016-01 | B77: 1.27 | C77: 1.5079 | D77: 1.06 | E77: 4.0524 | F77: 1.14 | G77: 4.401 | H77: 10.7063 | I77: 13.4205 | J77: 2.4517
A78: 2016-02 | B78: 0.9 | C78: 1.5215 | D78: 1 | E78: 3.9737 | F78: 1.29 | G78: 4.4034 | H78: 10.3563 | I78: 13.623 | J78: 2.9601
A79: 2016-03 | B79: 0.43 | C79: 1.528 | D79: 1.16 | E79: 3.7039 | F79: 0.51 | G79: 4.1213 | H79: 9.3869 | I79: 13.7579 | J79: 3.9959
A80: 2016-04 | B80: 0.61 | C80: 1.5373 | D80: 1.06 | E80: 3.5658 | F80: 0.33 | G80: 4.047 | H80: 9.2783 | I80: 13.8819 | J80: 4.2127
A81: 2016-05 | B81: 0.78 | C81: 1.5493 | D81: 1.11 | E81: 3.5393 | F81: 0.82 | G81: 4.0029 | H81: 9.3217 | I81: 14.0172 | J81: 4.2951
A82: 2016-06 | B82: 0.35 | C82: 1.5548 | D82: 1.16 | E82: 3.4245 | F82: 1.69 | G82: 3.8468 | H82: 8.8445 | I82: 14.1187 | J82: 4.8457
A83: 2016-07 | B83: 0.52 | C83: 1.5628 | D83: 1.11 | E83: 3.2756 | F83: 0.18 | G83: 3.6228 | H83: 8.7363 | I83: 14.0398 | J83: 4.8774
A84: 2016-08 | B84: 0.44 | C84: 1.5697 | D84: 1.22 | E84: 3.2097 | F84: 0.15 | G84: 3.5974 | H84: 8.975 | I84: 14.1638 | J84: 4.7615
A85: 2016-09 | B85: 0.08 | C85: 1.571 | D85: 1.11 | E85: 3.2564 | F85: 0.2 | G85: 3.652 | H85: 8.4764 | I85: 14.1638 | J85: 5.243
A86: 2016-10 | B86: 0.26 | C86: 1.5751 | D86: 1.05 | E86: 3.1858 | F86: 0.16 | G86: 3.5106 | H86: 7.8739 | I86: 14.0961 | J86: 5.768
A87: 2016-11 | B87: 0.18 | C87: 1.5779 | D87: 1.04 | E87: 3.342 | F87: -0.03 | G87: 3.6 | H87: 6.9875 | I87: 14.0735 | J87: 6.6232
A88: 2016-12 | B88: 0.3 | C88: 1.5826 | D88: 1.12 | E88: 3.3523 | F88: 0.54 | G88: 3.5333 | H88: 6.2881 | I88: 14.0284 | J88: 7.2824
...

Sheet BPR_Disjuntor
A1: Preço unitário de referência do disjuntor (ANEEL BPR) e correção pelo IPCA
A2: Fonte: ANEEL – Portal de Dados Abertos (dadosabertos.aneel.gov.br), acesso em 09/10/2026, licença ODbL. BPR – Banco de Preços de Referência (subestação), item-modulo-manobra, item "Disjuntor", classe UAR. Correção: fórmula com o índice IPCA da aba Macro_Mensal.
D3: mês final da correção: | E3: 2026-09
A4: tensao_kV | B4: mes_base_preco | C4: preco_base_R$ | D4: fator_IPCA_ate_2026-09 | E4: preco_corrigido_R$_2026-09
A5: 13.8 | B5: 2017-05 | C5: 63725.24 | D5: =INDEX(Macro_Mensal!$C$5:$C$205,MATCH($E$3,Macro_Mensal!$A$5:$A$205,0))/INDEX(Macro_Mensal!$C$5:$C$205,MATCH(B5,Macro_Mensal!$A$5:$A$205,0)) -> 1.588873 | E5: =C5*D5 -> 101251.31
A6: 69 | B6: 2017-05 | C6: 104938.8 | D6: =INDEX(Macro_Mensal!$C$5:$C$205,MATCH($E$3,Macro_Mensal!$A$5:$A$205,0))/INDEX(Macro_Mensal!$C$5:$C$205,MATCH(B6,Macro_Mensal!$A$5:$A$205,0)) -> 1.588873 | E6: =C6*D6 -> 166734.42
A7: 88 | B7: 2017-05 | C7: 137581.04 | D7: =INDEX(Macro_Mensal!$C$5:$C$205,MATCH($E$3,Macro_Mensal!$A$5:$A$205,0))/INDEX(Macro_Mensal!$C$5:$C$205,MATCH(B7,Macro_Mensal!$A$5:$A$205,0)) -> 1.588873 | E7: =C7*D7 -> 218598.8
A8: 138 | B8: 2017-05 | C8: 137581.04 | D8: =INDEX(Macro_Mensal!$C$5:$C$205,MATCH($E$3,Macro_Mensal!$A$5:$A$205,0))/INDEX(Macro_Mensal!$C$5:$C$205,MATCH(B8,Macro_Mensal!$A$5:$A$205,0)) -> 1.588873 | E8: =C8*D8 -> 218598.8
A9: 230 | B9: 2017-05 | C9: 292033.77 | D9: =INDEX(Macro_Mensal!$C$5:$C$205,MATCH($E$3,Macro_Mensal!$A$5:$A$205,0))/INDEX(Macro_Mensal!$C$5:$C$205,MATCH(B9,Macro_Mensal!$A$5:$A$205,0)) -> 1.588873 | E9: =C9*D9 -> 464004.56
A10: 345 | B10: 2017-05 | C10: 964538.65 | D10: =INDEX(Macro_Mensal!$C$5:$C$205,MATCH($E$3,Macro_Mensal!$A$5:$A$205,0))/INDEX(Macro_Mensal!$C$5:$C$205,MATCH(B10,Macro_Mensal!$A$5:$A$205,0)) -> 1.588873 | E10: =C10*D10 -> 1532529.4
A11: 440 | B11: 2017-05 | C11: 1870921.6 | D11: =INDEX(Macro_Mensal!$C$5:$C$205,MATCH($E$3,Macro_Mensal!$A$5:$A$205,0))/INDEX(Macro_Mensal!$C$5:$C$205,MATCH(B11,Macro_Mensal!$A$5:$A$205,0)) -> 1.588873 | E11: =C11*D11 -> 2972656.8
A12: 500 | B12: 2017-05 | C12: 1870921.6 | D12: =INDEX(Macro_Mensal!$C$5:$C$205,MATCH($E$3,Macro_Mensal!$A$5:$A$205,0))/INDEX(Macro_Mensal!$C$5:$C$205,MATCH(B12,Macro_Mensal!$A$5:$A$205,0)) -> 1.588873 | E12: =C12*D12 -> 2972656.8
A13: 750 | B13: 2017-05 | C13: 3332889.1 | D13: =INDEX(Macro_Mensal!$C$5:$C$205,MATCH($E$3,Macro_Mensal!$A$5:$A$205,0))/INDEX(Macro_Mensal!$C$5:$C$205,MATCH(B13,Macro_Mensal!$A$5:$A$205,0)) -> 1.588873 | E13: =C13*D13 -> 5295537.3

Sheet BPR_Modulos_Reator
A1: Custo total dos módulos de manobra (ANEEL BPR): conexão de reator de barra (CRB), de linha manobrável (CRL) e não manobrável (CRLn), e entrada de linha (EL)
A2: Fonte: ANEEL – Portal de Dados Abertos (dadosabertos.aneel.gov.br), acesso em 09/10/2026, licença ODbL. BPR – item-modulo-manobra; custo_total = Σ(preço × quantidade) dos itens do módulo.
A3: Valores nominais na base de preço de cada item (mai/2017 para equipamentos; dez/2011 para obras civis). Não corrigidos. O preço do reator em si não consta deste conjunto aberto.
A4: SigTipoModuloManobra | B4: NomTipoTensao | C4: DscTipoArranjo | D4: custo_total | E4: itens | F4: kv
A5: CRB | B5: 69 | C5: BD5 | D5: 936288.88 | E5: 35 | F5: 69
A6: CRB | B6: 69 | C6: BPT | D6: 829907.19 | E6: 35 | F6: 69
A7: CRB | B7: 69 | C7: BS | D7: 776716.35 | E7: 35 | F7: 69
A8: CRB | B8: 88 | C8: BD5 | D8: 1639700.8 | E8: 35 | F8: 88
A9: CRB | B9: 88 | C9: BPT | D9: 1521612.9 | E9: 35 | F9: 88
A10: CRB | B10: 88 | C10: BS | D10: 1462568.9 | E10: 35 | F10: 88
A11: CRB | B11: 138 | C11: BD4 | D11: 1580656.9 | E11: 35 | F11: 138
A12: CRB | B12: 138 | C12: BD5 | D12: 1639700.8 | E12: 35 | F12: 138
A13: CRB | B13: 138 | C13: BPT | D13: 1521612.9 | E13: 35 | F13: 138
A14: CRB | B14: 138 | C14: BS | D14: 1462568.9 | E14: 35 | F14: 138
